Okay, so the problem is that the user's shell program is failing a test where the output isn't being appended correctly. The test case involves using '>>' to append the output of a command to a file. Let me look through the provided code to see where the issue might be.

First, let's check how the code handles redirects. The split_redirects function is supposed to split tokens into parts like ">>" and the filename. Wait, the split_redirects function is supposed to handle operators like ">>", "1>>", etc. Let me see how that's implemented.

Looking at split_redirects: it checks for sequences like '1>>', '2>>', '>>', etc. The code seems to split the tokens correctly. For example, if the input is ">>file", it should split into ">>" and "file". But maybe there's an issue when the operator is part of a longer token. Let's see.

In the test case, the user runs "ls /tmp/baz >> /tmp/bar/bar.md". The split_redirects should split ">>" as a separate token. So in the parse_arguments step, the parts would be ["ls", "/tmp/baz", ">>", "/tmp/bar/bar.md"]. Then, during the processing of parts, the code checks for ">>" and sets stdout_redirect to (path, true) for append.

In the code, when processing the parts, the loop checks for ">" and ">>" etc. For ">>", it sets stdout_redirect with append = true. That's correct.

Now, when executing an external command (like 'ls'), the code uses Command and sets up stdout redirection. Let's look at the part where the Command is built.

In the _ => { ... } block (handling non-builtin commands), when setting up the command, the code checks if there's a stdout_redirect and opens the file with append mode. The OpenOptions are set with .append(*append) and .truncate(!*append). So when append is true, the file is opened in append mode and truncate is false, which should append to the file instead of truncating. That seems right.

But wait, maybe there's an issue with how the command's stdout is set. For example, in the code, when redirecting stdout, it does:

if let Some((file_path, append)) = &stdout_redirect {

match OpenOptions::new()

.create(true)

.write(true)

.append(*append)

.truncate(!*append)

.open(file_path) {

Ok(file) => {

cmd.stdout(file);

}

...

}

}

That looks correct. The append flag is used to open the file in append mode. So the output should be appended.

But the test is failing with the prompt not showing. The tester says: "Expected prompt ("$ ") but received """. Hmm. That suggests that after the 'ls' command is run, the shell doesn't print the next prompt. But why?

Wait, maybe the child process is not waiting for the command to finish, and the prompt is printed before the command completes. But in the code, when using Command::status(), which waits for the command to finish. So that should be okay.

Another possibility is that the code is not properly handling the redirection of the output, causing the command's output to interfere with the shell's own output. But the shell's output (the prompt) is written to stdout, and the command's output is redirected to a file. So they shouldn't interfere.

Wait, the problem could be in how the code handles the stdout and stderr files. Let's check if after redirecting stdout, the code is not writing the prompt to the same file. Because the shell's own output (like the prompt "$ ") is written to stdout, which might be redirected if the last command's redirection isn't properly reset. Wait, but each command is processed in a loop iteration. In each iteration, the code parses the command and sets up the redirections for that command only. Then, when the command is executed (as a child process), its stdout is redirected. The shell's own stdout (where it prints the prompt) should remain unaffected, as each child process has its own stdout.

Wait, but in the code, when the shell writes to stdout (like println!("$ ")), that's using the shell's own stdout, which is separate from the child process's stdout. So the shell's prompt should still go to the original stdout. Unless there's a case where the shell's code is somehow redirecting its own stdout. But looking at the code, the shell's own output (like the prompt) is written using println! and print!, which use the standard output. The redirections are applied only to the child process's Command. So the shell's stdout is not affected.

But the test is failing because after running the command, the prompt is not printed. So perhaps the code is not outputting the prompt after the command is executed. Let me look at the main loop.

The main loop is:

loop {

print!("$ ");

io::stdout().flush()?;

// read input

// process command

}

So after each command is processed, the loop goes back to printing the prompt. Unless the command is a built-in like 'exit', which exits the process.

But in the test case, the first command is 'ls -1 /tmp/baz >> /tmp/foo/foo.md'. After running this command, the shell should print the next prompt. But the tester's log shows "[your-program] $ ls -1 /tmp/baz >> /tmp/foo/foo.md" followed by "[tester::#EL9] Expected prompt ("$ ") but received """. So the tester sent the command and didn't see the next prompt.

Hmm. So maybe the shell is not printing the prompt again after the command is executed. Why?

Wait, perhaps the code is not handling some error in processing the command, causing the loop to exit early.

Looking at the main loop: after processing each command, the loop continues. Unless there's an error in reading input. Let's check the input reading part.

The code uses io::stdin().read_line(&mut input). On Ok(0), which is EOF, it breaks. Otherwise, it proceeds. So if the input is read correctly, the loop continues.

Wait, but in some cases, the code may return an error from the main function, causing the shell to exit. Let's check the return types.

The main function returns io::Result<()>. So any error during processing would exit the shell. But during command processing, most errors are handled with eprintln! and continue.

Wait, for example, in the 'echo' built-in, if the output file can't be opened, the code writes an error message to stderr and continues. So the main loop should keep running.

But perhaps in some code path, an error is returned from main, causing the shell to exit. For example, in the code for handling external commands, if there's an error opening the stdout file, the code writes an error message and continues. Let's check.

In the code when setting up stdout_redirect:

match OpenOptions::new()...open(file_path) {

Ok(file) => { cmd.stdout(file); }

Err(e) => {

let msg = ...;

if stderr_file is set, write to it, else eprintln!;

continue;

}

}

So the code uses 'continue' to skip the rest of the loop iteration. So the main loop should continue, prompting again.

Wait, but the code uses 'continue' which skips the rest of the loop body, so the shell would print the prompt again. So after an error in opening the file, the shell should print the prompt again.

But in the test case, there's no error. The command is 'ls -1 /tmp/baz >> /tmp/foo/foo.md', which should create the file if necessary and append.

Wait, but maybe the directory /tmp/foo doesn't exist. So when the code tries to open '/tmp/foo/foo.md', it returns an error. Then, the code writes an error message and continues. But the test's setup steps include creating some files. Wait, the setup steps for the test case might not have created the directory.

Looking at the test case:

In the example given, the user is supposed to run:

$ ls /tmp/baz >> /tmp/bar/bar.md

But the setup steps in the test might be creating /tmp/baz but not /tmp/bar, leading to a failure when opening the file. If the directory doesn't exist, the open would fail with "No such file or directory".

In that case, the code would output an error to stderr (or to the stderr file if redirected), and then continue. But in the test's error message, the problem is that the prompt is missing. So even if the command failed, the shell should still print the next prompt.

But according to the code, after handling the command (whether successful or not), the loop continues, printing the prompt again. Unless the error occurred in the main loop's input reading part.

Wait, in the code, after processing the command, the loop continues. So after handling the command, regardless of success, the shell should print the prompt again. The only way the prompt is not printed is if the main loop exits.

But why would the main loop exit?

Looking at the code, the main loop is a loop that runs until io::stdin().read_line returns Ok(0) (EOF), or an error occurs. So if the user enters a command that causes the code to return an error from main, then the shell exits.

Wait, but most of the code inside the loop uses ? to propagate errors. For example, in the main function:

print!("$ ");

io::stdout().flush()?;

If flushing fails, the error is returned from main, causing the shell to exit. Similarly, when reading the input:

match io::stdin().read_line(&mut input) {

Ok(0) => break,

Ok(_) => {}

Err(e) => {

eprintln!("Error: {}", e);

break;

}

}

Wait, here, if reading the line returns an error, the code prints an error message and breaks out of the loop, leading to the main function returning Ok(()). So the shell would exit after an IO error on stdin. But in normal cases, like when the command is processed, it should continue.

So in the test case, after the 'ls -1 ...' command is processed, the loop should print the prompt again. But the tester says that the prompt is missing. So perhaps the code is not outputting the prompt after the command is executed. Why?

Wait, maybe the code is not flushing stdout after printing the prompt. Let me check.

In the main loop:

print!("$ ");

io::stdout().flush()?;

Yes, the flush is called after printing the prompt. So the prompt should be visible immediately. Then the code reads input. But maybe the child process's output is being mixed with the shell's prompt. For example, if the child process's output is being written to the same stdout as the shell, but that's only if there was a redirection. Wait, in the test case, the redirection is to a file, so the child's stdout is redirected to the file. The shell's stdout is separate, so the prompt should be printed to the original stdout.

But perhaps in some cases, the child process's output is buffered, causing the shell's prompt to appear before the child's output. But that shouldn't affect the presence of the prompt. The tester is expecting the prompt after the command is executed.

Wait, maybe the code is not handling the case where the command's execution takes a long time, but in the test environment, the command (ls) is quick. So that's not the issue.

Alternatively, maybe the code is not handling the command correctly, causing the loop to exit. Let me check the code path when executing an external command.

When the code runs an external command, it uses Command::status(), which waits for the command to finish. Then, the code continues. So after the command is executed, the loop should print the prompt again.

Wait, but in the code, after handling the command (in the match block), the code proceeds to the next iteration of the loop. So after the command is processed, the code should print the prompt again.

So why isn't the prompt appearing in the test?

Let me look at the test's error message again: "Expected prompt ("$ ") but received """. So the test sent the command, and after the command was executed, the tester expects the next prompt, but received nothing. So perhaps the shell's code isn't printing the prompt after the command is executed.

But according to the code, the loop starts by printing the prompt, then reading input. So each iteration of the loop is: print prompt, read input, process command, loop again.

Wait, no. Wait, the loop structure is:

loop {

print prompt and flush;

read input;

process command;

}

So after processing the command, the loop starts over, printing the prompt again. So each command processed should result in a new prompt.

But in the test case, after the first command (ls ...), the shell isn't printing the prompt again. That suggests that the code is not looping back to print the prompt again. Why?

Ah! Maybe the code is stuck in an error path that skips the loop's next iteration. Let me check.

Looking at the code for processing the command: after parsing the parts, if command_args is empty, the code continues, which skips the rest of the loop and starts over. Otherwise, it processes the command.

So after processing the command, the loop should start over, printing the prompt.

But if during command processing, the code returns an error (which would propagate up), the main function would exit. Let me check all the possible error paths in command processing.

For example, in the 'echo' built-in, if there's an error writing to the file, the code uses map_err to return an error. But wait, in the code:

For 'echo', when redirecting to a file:

let mut file = OpenOptions::new()...open(file_path).map_err(...)?;

The map_err returns an io::Error, and the ? operator would return that error from the main function. So if opening the file fails (e.g., the directory doesn't exist), the code returns an error, causing the shell to exit.

Ah! That's the problem. If during the processing of a built-in command (like echo), there's an error opening the output file, the code returns an error from main, causing the shell to exit, which is why the next prompt isn't printed.

Wait, let's look at the code for the 'echo' built-in:

if let Some((file_path, append)) = &stdout_redirect {

let mut file = OpenOptions::new()

.create(true)

.write(true)

.append(*append)

.truncate(!*append)

.open(file_path)

.map_err(|e| {

let msg = format!("Error opening file: {}", e);

if let Some(file) = &mut stderr_file {

writeln!(file, "{}", msg).ok();

} else {

eprintln!("{}", msg);

}

io::Error::new(io::ErrorKind::Other, e)

})?;

writeln!(file, "{}", output).map_err(|e| {

let msg = format!("Error writing to file: {}", e);

if let Some(file) = &mut stderr_file {

writeln!(file, "{}", msg).ok();

} else {

eprintln!("{}", msg);

}

io::Error::new(io::ErrorKind::Other, e)

})?;

}

Here, when opening the file, if there's an error, the code creates a new io::Error and returns it with ?. So that error propagates to the main function, causing it to return an Err, and thus the shell exits.

This is a problem because if there's an error opening the output file (like the directory doesn't exist), the shell would exit instead of printing an error message and continuing.

So the code should handle these errors without propagating them. For example, in the 'echo' built-in, after encountering an error when opening the file, the code should print an error message and continue the loop, instead of returning an error from main.

But currently, the code uses ? which returns the error. So in such cases, the shell would exit.

This explains why the prompt isn't printed: the shell exits after an error in processing the command.

So the fix is to remove the ? operator and instead handle the error without propagating it.

Let me check where the ? is used. For example, in the 'echo' code:

map_err(...)?;

The map_err converts the original error into a new io::Error and then the ? returns it from the current function (which is main's loop body), causing main to return an error and the shell to exit.

So instead of using ?, the code should handle the error and continue the loop.

So how to fix this?

In the code, during the processing of built-in commands, any errors when opening or writing to files should be handled without propagating errors. Instead of using ?, the code should check for errors and print error messages, then continue.

But the code is written to use ? which propagates errors, which would exit the shell.

So the solution is to replace the ? with explicit error handling.

For example, in the 'echo' built-in:

Instead of:

writeln!(file, "{}", output).map_err(...)?;

We should use:

if let Err(e) = writeln!(file, "{}", output) {

// handle error

}

But modifying all instances of ? in built-in commands.

This is a significant change, as all error handling in built-ins is currently using ? which exits the shell on any error.

So the problem is that in cases where the redirection can't be done (like the directory doesn't exist), the shell exits instead of printing an error message and continuing.

In the test case provided, the error may be that the directory /tmp/foo doesn't exist, so trying to open /tmp/foo/foo.md would fail. The shell then exits, so the prompt isn't printed.

To fix this, the code should handle errors during file operations in built-in commands without propagating them.

Let's look at the 'echo' example again. The code for opening the file and writing to it uses map_err and then ?, which propagates the error. We need to change that to not propagate.

For example, in the 'echo' code:

let mut file = match OpenOptions::new()

.create(true)

.write(true)

.append(*append)

.truncate(!*append)

.open(file_path)

{

Ok(file) => file,

Err(e) => {

let msg = format!("Error opening file: {}", e);

if let Some(file) = &mut stderr_file {

writeln!(file, "{}", msg).ok();

} else {

eprintln!("{}", msg);

}

continue; // skip writing to the file

}

};

Similarly, when writing to the file:

if let Err(e) = writeln!(file, "{}", output) {

let msg = format!("Error writing to file: {}", e);

if let Some(file) = &mut stderr_file {

writeln!(file, "{}", msg).ok();

} else {

eprintln!("{}", msg);

}

}

This way, any errors during opening or writing the file are handled, and the shell continues to the next iteration of the loop.

But in the current code, the code is using map_err to create an error and then using ? to return it. So the fix would be to replace those ? with explicit error handling.

This applies to all built-in commands (echo, type, pwd, cd) when handling redirections.

For example, in the 'type' command:

When opening the file for redirection:

let mut file = OpenOptions::new()...open(file_path)

.map_err(...)?;

This would return an error and exit the shell. Instead, it should handle the error and continue.

So the fix would be to replace the map_err and ? with a match statement.

The same applies to other built-in commands where redirection is done.

So the root cause of the test failure is that when the output redirection fails (e.g., directory doesn't exist), the shell exits instead of printing an error and continuing, leading to the prompt not being displayed.

To resolve this, all error handling in built-in commands related to redirection should be changed to not propagate errors to main, but handle them and continue.

Now, modifying the code accordingly.

For example, in the 'echo' built-in code:

Original code:

let mut file = OpenOptions::new()

.create(true)

.write(true)

.append(*append)

.truncate(!*append)

.open(file_path)

.map_err(|e| {

// ... error message ...

io::Error::new(io::ErrorKind::Other, e)

})?;

writeln!(file, "{}", output).map_err(|e| {

// ... error message ...

io::Error::new(io::ErrorKind::Other, e)

})?;

Modified code:

let mut file = match OpenOptions::new()

.create(true)

.write(true)

.append(*append)

.truncate(!*append)

.open(file_path)

{

Ok(file) => file,

Err(e) => {

let msg = format!("Error opening file: {}", e);

if let Some(file) = &mut stderr_file {

writeln!(file, "{}", msg).ok();

} else {

eprintln!("{}", msg);

}

continue;

}

};

if let Err(e) = writeln!(file, "{}", output) {

let msg = format!("Error writing to file: {}", e);

if let Some(file) = &mut stderr_file {

writeln!(file, "{}", msg).ok();

} else {

eprintln!("{}", msg);

}

}

This way, errors in opening or writing the file are handled without causing the shell to exit.

The same approach needs to be applied to all other instances where ? is used in handling file operations in built-in commands.

By making these changes, the shell will continue to run after encountering errors, print the error messages to stderr (or redirected stderr), and then display the prompt again for the next command.

Once these changes are made, the test case should pass because the shell will handle the error (if any) and continue, ensuring that the prompt is printed after each command.